Workbook

Sheet Training
A1: resultsPro/1_1 | B1: resultsPro/1_1 | C1: resultsPro/1_1 | D1: resultsPro/1_1 | E1: resultsPro/1_1 | F1: resultsPro/2_1 | G1: resultsPro/2_1 | H1: resultsPro/2_1 | I1: resultsPro/2_1 | J1: resultsPro/2_1 | K1: resultsPro/3_1 | L1: resultsPro/3_1 | M1: resultsPro/3_1 | N1: resultsPro/3_1 | O1: resultsPro/3_1 | P1: resultsPro/4_1 | Q1: resultsPro/4_1 | R1: resultsPro/4_1 | S1: resultsPro/4_1 | T1: resultsPro/4_1 | U1: resultsPro/5_1 | V1: resultsPro/5_1 | W1: resultsPro/5_1 | X1: resultsPro/5_1 | Y1: resultsPro/5_1 | Z1: resultsPro/6_1 | AA1: resultsPro/6_1 | AB1: resultsPro/6_1 | AC1: resultsPro/6_1 | AD1: resultsPro/6_1 | AE1: resultsPro/7_1 | AF1: resultsPro/7_1 | AG1: resultsPro/7_1 | AH1: resultsPro/7_1 | AI1: resultsPro/7_1 | AJ1: resultsPro/8_1 | AK1: resultsPro/8_1 | AL1: resultsPro/8_1 | AM1: resultsPro/8_1 | AN1: resultsPro/8_1 | AO1: resultsPro/9_1 | AP1: resultsPro/9_1 | AQ1: resultsPro/9_1 | AR1: resultsPro/9_1 | AS1: resultsPro/9_1 | AT1: resultsPro/10_1 | AU1: resultsPro/10_1 | AV1: resultsPro/10_1 | AW1: resultsPro/10_1 | AX1: resultsPro/10_1 | AY1: resultsPro/11_1 | AZ1: resultsPro/11_1 | BA1: resultsPro/11_1 | BB1: resultsPro/11_1 | BC1: resultsPro/11_1 | BD1: resultsPro/12_1 | BE1: resultsPro/12_1 | BF1: resultsPro/12_1 | BG1: resultsPro/12_1 | BH1: resultsPro/12_1 | BI1: resultsPro/13_1 | BJ1: resultsPro/13_1 | BK1: resultsPro/13_1 | BL1: resultsPro/13_1 | BM1: resultsPro/13_1 | BN1: resultsPro/14_1 | BO1: resultsPro/14_1 | BP1: resultsPro/14_1 | BQ1: resultsPro/14_1 | BR1: resultsPro/14_1 | BS1: resultsPro/15_1 | BT1: resultsPro/15_1 | BU1: resultsPro/15_1 | BV1: resultsPro/15_1 | BW1: resultsPro/15_1 | BX1: resultsPro/16_1 | BY1: resultsPro/16_1 | BZ1: resultsPro/16_1 | CA1: resultsPro/16_1 | CB1: resultsPro/16_1 | CC1: resultsPro/17_1 | CD1: resultsPro/17_1 | CE1: resultsPro/17_1 | CF1: resultsPro/17_1 | CG1: resultsPro/17_1 | CH1: resultsPro/18_1 | CI1: resultsPro/18_1 | CJ1: resultsPro/18_1 | CK1: resultsPro/18_1 | CL1: resultsPro/18_1 | CM1: resultsPro/19_1 | CN1: resultsPro/19_1 | CO1: resultsPro/19_1 | CP1: resultsPro/19_1 | CQ1: resultsPro/19_1
A2: 96.428571 | B2: 97.647059 | C2: 97.647059 | D2: 98.823529 | E2: 96.470588 | F2: 95.238095 | G2: 98.823529 | H2: 96.470588 | I2: 95.294118 | J2: 96.470588 | K2: 95.238095 | L2: 95.294118 | M2: 100 | N2: 95.294118 | O2: 96.470588 | P2: 95.238095 | Q2: 96.470588 | R2: 96.470588 | S2: 95.294118 | T2: 96.470588 | U2: 95.238095 | V2: 95.294118 | W2: 96.470588 | X2: 98.823529 | Y2: 96.470588 | Z2: 95.238095 | AA2: 96.470588 | AB2: 97.647059 | AC2: 96.470588 | AD2: 96.470588 | AE2: 95.238095 | AF2: 98.823529 | AG2: 95.294118 | AH2: 95.294118 | AI2: 96.470588 | AJ2: 95.238095 | AK2: 96.470588 | AL2: 96.470588 | AM2: 95.294118 | AN2: 96.470588 | AO2: 95.238095 | AP2: 96.470588 | AQ2: 96.470588 | AR2: 98.823529 | AS2: 95.294118 | AT2: 95.238095 | AU2: 95.294118 | AV2: 94.117647 | AW2: 95.294118 | AX2: 95.294118 | AY2: 95.238095 | AZ2: 97.647059 | BA2: 95.294118 | BB2: 95.294118 | BC2: 96.470588 | BD2: 96.428571 | BE2: 96.470588 | BF2: 96.470588 | BG2: 94.117647 | BH2: 95.294118 | BI2: 95.238095 | BJ2: 98.823529 | BK2: 97.647059 | BL2: 95.294118 | BM2: 95.294118 | BN2: 96.428571 | BO2: 96.470588 | BP2: 97.647059 | BQ2: 96.470588 | BR2: 96.470588 | BS2: 96.428571 | BT2: 96.470588 | BU2: 96.470588 | BV2: 95.294118 | BW2: 96.470588 | BX2: 95.238095 | BY2: 98.823529 | BZ2: 95.294118 | CA2: 95.294118 | CB2: 95.294118 | CC2: 95.238095 | CD2: 96.470588 | CE2: 95.294118 | CF2: 95.294118 | CG2: 96.470588 | CH2: 95.238095 | CI2: 95.294118 | CJ2: 94.117647 | CK2: 95.294118 | CL2: 95.294118 | CM2: 95.238095 | CN2: 97.647059 | CO2: 96.470588 | CP2: 95.294118 | CQ2: 96.470588
A3: 86.4 | B3: 82.6 | C3: 86.8 | D3: 86.4 | E3: 86.4 | F3: 87 | G3: 87 | H3: 84.6 | I3: 86.2 | J3: 87 | K3: 86.4 | L3: 86.6 | M3: 85.8 | N3: 86.4 | O3: 86.2 | P3: 86.2 | Q3: 86.4 | R3: 85 | S3: 85 | T3: 84.2 | U3: 87.2 | V3: 86 | W3: 86.4 | X3: 87 | Y3: 86 | Z3: 92.2 | AA3: 92.2 | AB3: 92 | AC3: 91.8 | AD3: 92.2 | AE3: 91.8 | AF3: 91.4 | AG3: 91.4 | AH3: 91.8 | AI3: 92 | AJ3: 85.4 | AK3: 86.2 | AL3: 88 | AM3: 85.8 | AN3: 85.2 | AO3: 85.2 | AP3: 85.4 | AQ3: 84.8 | AR3: 87.6 | AS3: 86 | AT3: 91.4 | AU3: 91.2 | AV3: 91.2 | AW3: 91.4 | AX3: 90.8 | AY3: 92.2 | AZ3: 92.2 | BA3: 91.6 | BB3: 92 | BC3: 92.2 | BD3: 85.6 | BE3: 86 | BF3: 84 | BG3: 86.8 | BH3: 84.6 | BI3: 91.8 | BJ3: 92.2 | BK3: 91.6 | BL3: 92.2 | BM3: 92 | BN3: 87.2 | BO3: 86.4 | BP3: 86 | BQ3: 86.8 | BR3: 87 | BS3: 84.8 | BT3: 83.2 | BU3: 85.6 | BV3: 85.6 | BW3: 86.4 | BX3: 91.6 | BY3: 91.6 | BZ3: 91.6 | CA3: 91.6 | CB3: 92 | CC3: 92.2 | CD3: 92.2 | CE3: 92 | CF3: 92 | CG3: 92 | CH3: 91.4 | CI3: 91.2 | CJ3: 91.2 | CK3: 91.4 | CL3: 90.8 | CM3: 92.2 | CN3: 92.2 | CO3: 92 | CP3: 92.2 | CQ3: 92.2
A4: 87.688679 | B4: 86.627358 | C4: 86.34434 | D4: 84.316038 | E4: 84.834906 | F4: 87.688679 | G4: 88.066038 | H4: 86.34434 | I4: 86.792453 | J4: 87.146226 | K4: 84.033019 | L4: 85.117925 | M4: 85.141509 | N4: 84.103774 | O4: 85.424528 | P4: 85.542453 | Q4: 88.089623 | R4: 86.226415 | S4: 84.386792 | T4: 84.834906 | U4: 87.665094 | V4: 85.283019 | W4: 85.943396 | X4: 86.273585 | Y4: 87.075472 | Z4: 84.504717 | AA4: 86.273585 | AB4: 82.712264 | AC4: 84.103774 | AD4: 86.320755 | AE4: 87.688679 | AF4: 86.320755 | AG4: 86.25 | AH4: 84.127358 | AI4: 86.014151 | AJ4: 86.981132 | AK4: 88.066038 | AL4: 86.037736 | AM4: 87.877358 | AN4: 84.834906 | AO4: 85.589623 | AP4: 87.099057 | AQ4: 85.495283 | AR4: 85.259434 | AS4: 84.433962 | AT4: 86.273585 | AU4: 86.415094 | AV4: 86.462264 | AW4: 83.443396 | AX4: 85.353774 | AY4: 85.849057 | AZ4: 85.919811 | BA4: 83.419811 | BB4: 83.419811 | BC4: 86.816038 | BD4: 86.816038 | BE4: 85.09434 | BF4: 84.693396 | BG4: 85.283019 | BH4: 87.429245 | BI4: 84.976415 | BJ4: 83.820755 | BK4: 84.056604 | BL4: 83.962264 | BM4: 87.287736 | BN4: 87.051887 | BO4: 86.933962 | BP4: 86.320755 | BQ4: 86.650943 | BR4: 85.400943 | BS4: 85.141509 | BT4: 85.518868 | BU4: 83.867925 | BV4: 84.575472 | BW4: 85.825472 | BX4: 85.778302 | BY4: 83.679245 | BZ4: 85.283019 | CA4: 86.533019 | CB4: 85.919811 | CC4: 84.95283 | CD4: 87.523585 | CE4: 87.59434 | CF4: 84.882075 | CG4: 86.509434 | CH4: 86.273585 | CI4: 86.415094 | CJ4: 86.462264 | CK4: 83.443396 | CL4: 85.353774 | CM4: 85.495283 | CN4: 85.613208 | CO4: 84.882075 | CP4: 85.212264 | CQ4: 87.216981
A5: 90 | B5: 88.054608 | C5: 87.972509 | D5: 91.496599 | E5: 86.643836 | F5: 89.655172 | G5: 87.372014 | H5: 85.56701 | I5: 88.435374 | J5: 85.616438 | K5: 90 | L5: 88.054608 | M5: 88.316151 | N5: 85.034014 | O5: 86.643836 | P5: 87.931034 | Q5: 88.737201 | R5: 87.628866 | S5: 88.77551 | T5: 88.356164 | U5: 89.310345 | V5: 87.372014 | W5: 86.941581 | X5: 88.435374 | Y5: 87.328767 | Z5: 90 | AA5: 86.348123 | AB5: 85.56701 | AC5: 87.07483 | AD5: 89.726027 | AE5: 90.344828 | AF5: 90.102389 | AG5: 88.659794 | AH5: 90.816327 | AI5: 90.068493 | AJ5: 88.965517 | AK5: 87.372014 | AL5: 87.285223 | AM5: 89.795918 | AN5: 88.013699 | AO5: 88.275862 | AP5: 88.054608 | AQ5: 87.285223 | AR5: 86.734694 | AS5: 86.30137 | AT5: 91.034483 | AU5: 87.372014 | AV5: 89.690722 | AW5: 89.455782 | AX5: 89.041096 | AY5: 90 | AZ5: 87.713311 | BA5: 90.378007 | BB5: 89.115646 | BC5: 88.69863 | BD5: 88.62069 | BE5: 88.737201 | BF5: 89.690722 | BG5: 84.693878 | BH5: 89.041096 | BI5: 90.344828 | BJ5: 88.737201 | BK5: 90.034364 | BL5: 89.115646 | BM5: 89.383562 | BN5: 90.689655 | BO5: 89.078498 | BP5: 86.941581 | BQ5: 87.414966 | BR5: 88.013699 | BS5: 89.310345 | BT5: 86.68942 | BU5: 86.941581 | BV5: 86.734694 | BW5: 86.986301 | BX5: 90 | BY5: 88.395904 | BZ5: 90.378007 | CA5: 90.47619 | CB5: 88.69863 | CC5: 91.034483 | CD5: 88.737201 | CE5: 90.378007 | CF5: 89.115646 | CG5: 88.69863 | CH5: 91.034483 | CI5: 87.372014 | CJ5: 89.690722 | CK5: 89.455782 | CL5: 89.041096 | CM5: 91.724138 | CN5: 89.078498 | CO5: 90.378007 | CP5: 89.455782 | CQ5: 89.726027
A6: 78.985507 | B6: 81.884058 | C6: 80.072464 | D6: 80.072464 | E6: 79.347826 | F6: 77.898551 | G6: 80.072464 | H6: 77.898551 | I6: 78.26087 | J6: 80.434783 | K6: 78.26087 | L6: 79.710145 | M6: 78.985507 | N6: 79.710145 | O6: 78.623188 | P6: 76.449275 | Q6: 81.15942 | R6: 79.710145 | S6: 81.521739 | T6: 80.072464 | U6: 78.26087 | V6: 81.884058 | W6: 79.710145 | X6: 80.072464 | Y6: 81.521739 | Z6: 77.173913 | AA6: 79.710145 | AB6: 79.347826 | AC6: 76.449275 | AD6: 77.536232 | AE6: 80.797101 | AF6: 81.521739 | AG6: 80.072464 | AH6: 78.623188 | AI6: 78.26087 | AJ6: 77.898551 | AK6: 83.333333 | AL6: 81.884058 | AM6: 80.797101 | AN6: 82.246377 | AO6: 78.985507 | AP6: 81.884058 | AQ6: 78.623188 | AR6: 80.434783 | AS6: 82.971014 | AT6: 77.173913 | AU6: 80.072464 | AV6: 76.086957 | AW6: 78.985507 | AX6: 78.985507 | AY6: 81.15942 | AZ6: 85.507246 | BA6: 77.898551 | BB6: 79.710145 | BC6: 80.797101 | BD6: 79.347826 | BE6: 80.072464 | BF6: 79.710145 | BG6: 78.26087 | BH6: 81.15942 | BI6: 81.15942 | BJ6: 83.333333 | BK6: 80.434783 | BL6: 79.710145 | BM6: 80.797101 | BN6: 77.898551 | BO6: 82.971014 | BP6: 79.710145 | BQ6: 80.797101 | BR6: 80.797101 | BS6: 75.724638 | BT6: 80.434783 | BU6: 79.347826 | BV6: 79.710145 | BW6: 79.710145 | BX6: 81.521739 | BY6: 84.782609 | BZ6: 81.521739 | CA6: 79.347826 | CB6: 80.434783 | CC6: 80.797101 | CD6: 84.782609 | CE6: 82.246377 | CF6: 79.710145 | CG6: 80.434783 | CH6: 77.173913 | CI6: 80.072464 | CJ6: 76.086957 | CK6: 78.985507 | CL6: 78.985507 | CM6: 82.608696 | CN6: 81.15942 | CO6: 82.246377 | CP6: 78.985507 | CQ6: 80.072464
A7: 89.029536 | B7: 91.139241 | C7: 90.336134 | D7: 89.915966 | E7: 91.176471 | F7: 87.341772 | G7: 90.7173 | H7: 89.07563 | I7: 90.336134 | J7: 89.495798 | K7: 86.919831 | L7: 90.295359 | M7: 89.915966 | N7: 90.336134 | O7: 89.07563 | P7: 89.029536 | Q7: 90.295359 | R7: 90.756303 | S7: 89.915966 | T7: 88.235294 | U7: 86.075949 | V7: 90.7173 | W7: 90.756303 | X7: 89.495798 | Y7: 87.394958 | Z7: 89.029536 | AA7: 88.185654 | AB7: 89.915966 | AC7: 87.394958 | AD7: 87.815126 | AE7: 89.873418 | AF7: 90.7173 | AG7: 89.07563 | AH7: 92.016807 | AI7: 89.07563 | AJ7: 89.029536 | AK7: 90.7173 | AL7: 89.495798 | AM7: 91.176471 | AN7: 90.336134 | AO7: 88.185654 | AP7: 91.139241 | AQ7: 90.336134 | AR7: 90.336134 | AS7: 86.134454 | AT7: 89.873418 | AU7: 89.029536 | AV7: 90.336134 | AW7: 90.756303 | AX7: 89.495798 | AY7: 88.607595 | AZ7: 90.295359 | BA7: 89.495798 | BB7: 92.857143 | BC7: 89.07563 | BD7: 86.49789 | BE7: 91.139241 | BF7: 89.495798 | BG7: 89.07563 | BH7: 89.495798 | BI7: 89.873418 | BJ7: 91.139241 | BK7: 89.915966 | BL7: 90.756303 | BM7: 89.915966 | BN7: 89.451477 | BO7: 90.7173 | BP7: 90.336134 | BQ7: 92.016807 | BR7: 88.235294 | BS7: 88.607595 | BT7: 91.561181 | BU7: 89.915966 | BV7: 90.756303 | BW7: 87.815126 | BX7: 88.607595 | BY7: 89.451477 | BZ7: 90.336134 | CA7: 91.596639 | CB7: 88.655462 | CC7: 87.763713 | CD7: 89.873418 | CE7: 88.655462 | CF7: 92.016807 | CG7: 89.07563 | CH7: 89.873418 | CI7: 89.029536 | CJ7: 90.336134 | CK7: 90.756303 | CL7: 89.495798 | CM7: 88.607595 | CN7: 90.7173 | CO7: 89.915966 | CP7: 91.176471 | CQ7: 89.915966
A8: 60.441426 | B8: 59.762309 | C8: 61.544992 | D8: 60.729432 | E8: 60.050891 | F8: 59.847199 | G8: 60.356537 | H8: 60.441426 | I8: 59.796438 | J8: 60.899067 | K8: 58.149406 | L8: 60.101868 | M8: 59.083192 | N8: 59.287532 | O8: 58.608991 | P8: 58.743633 | Q8: 60.016978 | R8: 59.252971 | S8: 60.220526 | T8: 58.26972 | U8: 59.932088 | V8: 60.611205 | W8: 61.205433 | X8: 59.372349 | Y8: 60.390161 | Z8: 61.205433 | AA8: 62.478778 | AB8: 62.478778 | AC8: 62.256149 | AD8: 62.59542 | AE8: 62.139219 | AF8: 62.139219 | AG8: 62.563667 | AH8: 61.662426 | AI8: 62.086514 | AJ8: 60.696095 | AK8: 60.950764 | AL8: 59.337861 | AM8: 58.948261 | AN8: 59.372349 | AO8: 59.932088 | AP8: 60.101868 | AQ8: 60.441426 | AR8: 58.693808 | AS8: 58.778626 | AT8: 61.205433 | AU8: 60.780985 | AV8: 60.441426 | AW8: 61.662426 | AX8: 61.916879 | AY8: 62.988115 | AZ8: 62.224109 | BA8: 62.478778 | BB8: 61.832061 | BC8: 62.001696 | BD8: 58.573854 | BE8: 59.337861 | BF8: 60.356537 | BG8: 59.202714 | BH8: 59.966073 | BI8: 62.478778 | BJ8: 62.903226 | BK8: 62.648557 | BL8: 63.189143 | BM8: 62.086514 | BN8: 60.611205 | BO8: 60.865874 | BP8: 60.696095 | BQ8: 60.644614 | BR8: 60.474979 | BS8: 59.847199 | BT8: 59.847199 | BU8: 60.526316 | BV8: 59.372349 | BW8: 57.167091 | BX8: 62.308998 | BY8: 60.356537 | BZ8: 62.054329 | CA8: 62.171332 | CB8: 62.171332 | CC8: 63.073005 | CD8: 63.327674 | CE8: 62.648557 | CF8: 63.443596 | CG8: 63.613232 | CH8: 61.205433 | CI8: 60.780985 | CJ8: 60.441426 | CK8: 61.662426 | CL8: 61.916879 | CM8: 63.752122 | CN8: 63.752122 | CO8: 62.818336 | CP8: 63.528414 | CQ8: 62.171332
A9: 88.80597 | B9: 90.334572 | C9: 90.334572 | D9: 86.988848 | E9: 91.821561 | F9: 90.671642 | G9: 90.70632 | H9: 90.70632 | I9: 90.334572 | J9: 89.591078 | K9: 89.925373 | L9: 91.078067 | M9: 91.078067 | N9: 89.219331 | O9: 91.821561 | P9: 90.298507 | Q9: 90.334572 | R9: 90.334572 | S9: 88.847584 | T9: 91.449814 | U9: 88.432836 | V9: 90.334572 | W9: 90.334572 | X9: 88.475836 | Y9: 91.449814 | Z9: 92.537313 | AA9: 91.078067 | AB9: 92.193309 | AC9: 88.847584 | AD9: 91.821561 | AE9: 91.41791 | AF9: 90.334572 | AG9: 91.821561 | AH9: 90.70632 | AI9: 92.193309 | AJ9: 89.925373 | AK9: 89.591078 | AL9: 91.078067 | AM9: 88.104089 | AN9: 90.70632 | AO9: 88.80597 | AP9: 89.962825 | AQ9: 90.334572 | AR9: 89.591078 | AS9: 89.591078 | AT9: 91.41791 | AU9: 91.449814 | AV9: 91.449814 | AW9: 89.591078 | AX9: 93.30855 | AY9: 90.671642 | AZ9: 89.591078 | BA9: 90.334572 | BB9: 86.245353 | BC9: 91.449814 | BD9: 90.671642 | BE9: 89.962825 | BF9: 90.334572 | BG9: 88.475836 | BH9: 90.334572 | BI9: 90.671642 | BJ9: 89.962825 | BK9: 90.334572 | BL9: 89.591078 | BM9: 90.334572 | BN9: 90.298507 | BO9: 89.219331 | BP9: 89.962825 | BQ9: 88.847584 | BR9: 92.193309 | BS9: 89.552239 | BT9: 89.219331 | BU9: 89.219331 | BV9: 88.104089 | BW9: 90.334572 | BX9: 89.552239 | BY9: 90.334572 | BZ9: 91.078067 | CA9: 90.334572 | CB9: 92.565056 | CC9: 91.41791 | CD9: 89.962825 | CE9: 90.334572 | CF9: 88.104089 | CG9: 91.078067 | CH9: 91.41791 | CI9: 91.449814 | CJ9: 91.449814 | CK9: 89.591078 | CL9: 93.30855 | CM9: 91.791045 | CN9: 89.962825 | CO9: 90.70632 | CP9: 89.962825 | CQ9: 92.565056
A10: 81.28655 | B10: 86.549708 | C10: 85.380117 | D10: 80.701754 | E10: 83.139535 | F10: 84.210526 | G10: 87.134503 | H10: 87.719298 | I10: 80.116959 | J10: 83.139535 | K10: 84.795322 | L10: 84.795322 | M10: 86.549708 | N10: 84.210526 | O10: 83.72093 | P10: 83.625731 | Q10: 85.380117 | R10: 84.795322 | S10: 81.871345 | T10: 84.302326 | U10: 81.871345 | V10: 85.964912 | W10: 84.795322 | X10: 85.380117 | Y10: 83.72093 | Z10: 82.45614 | AA10: 84.210526 | AB10: 87.719298 | AC10: 80.701754 | AD10: 80.232558 | AE10: 84.795322 | AF10: 86.549708 | AG10: 85.964912 | AH10: 81.28655 | AI10: 84.302326 | AJ10: 81.28655 | AK10: 87.134503 | AL10: 85.380117 | AM10: 81.871345 | AN10: 81.976744 | AO10: 81.28655 | AP10: 84.210526 | AQ10: 85.380117 | AR10: 80.701754 | AS10: 82.55814 | AT10: 82.45614 | AU10: 85.964912 | AV10: 83.625731 | AW10: 81.871345 | AX10: 83.72093 | AY10: 82.45614 | AZ10: 84.210526 | BA10: 85.380117 | BB10: 81.28655 | BC10: 84.883721 | BD10: 82.45614 | BE10: 83.040936 | BF10: 87.134503 | BG10: 81.871345 | BH10: 81.976744 | BI10: 82.45614 | BJ10: 83.625731 | BK10: 88.304094 | BL10: 82.45614 | BM10: 83.139535 | BN10: 81.28655 | BO10: 85.964912 | BP10: 87.134503 | BQ10: 83.625731 | BR10: 83.139535 | BS10: 81.871345 | BT10: 84.795322 | BU10: 85.964912 | BV10: 81.28655 | BW10: 81.976744 | BX10: 82.45614 | BY10: 84.210526 | BZ10: 83.625731 | CA10: 81.28655 | CB10: 84.302326 | CC10: 83.625731 | CD10: 85.964912 | CE10: 85.964912 | CF10: 81.28655 | CG10: 83.139535 | CH10: 82.45614 | CI10: 85.964912 | CJ10: 83.625731 | CK10: 81.871345 | CL10: 83.72093 | CM10: 83.040936 | CN10: 85.380117 | CO10: 85.964912 | CP10: 81.28655 | CQ10: 84.302326
A11: 83.196721 | B11: 82.857143 | C11: 82.857143 | D11: 84.897959 | E11: 83.265306 | F11: 83.196721 | G11: 84.081633 | H11: 84.897959 | I11: 84.081633 | J11: 82.857143 | K11: 82.786885 | L11: 82.44898 | M11: 84.081633 | N11: 84.897959 | O11: 83.673469 | P11: 82.377049 | Q11: 83.265306 | R11: 83.673469 | S11: 84.897959 | T11: 83.673469 | U11: 82.786885 | V11: 82.44898 | W11: 84.081633 | X11: 83.673469 | Y11: 83.265306 | Z11: 81.557377 | AA11: 83.673469 | AB11: 81.632653 | AC11: 82.44898 | AD11: 84.081633 | AE11: 81.967213 | AF11: 83.673469 | AG11: 82.44898 | AH11: 82.857143 | AI11: 82.44898 | AJ11: 84.42623 | AK11: 84.897959 | AL11: 84.489796 | AM11: 83.265306 | AN11: 84.081633 | AO11: 83.196721 | AP11: 84.489796 | AQ11: 82.44898 | AR11: 82.857143 | AS11: 85.306122 | AT11: 80.327869 | AU11: 83.265306 | AV11: 82.040816 | AW11: 82.857143 | AX11: 82.857143 | AY11: 81.967213 | AZ11: 82.44898 | BA11: 82.857143 | BB11: 84.081633 | BC11: 82.040816 | BD11: 82.786885 | BE11: 82.857143 | BF11: 83.673469 | BG11: 84.489796 | BH11: 83.265306 | BI11: 82.377049 | BJ11: 81.632653 | BK11: 82.44898 | BL11: 81.632653 | BM11: 83.265306 | BN11: 84.42623 | BO11: 83.265306 | BP11: 84.489796 | BQ11: 84.081633 | BR11: 82.44898 | BS11: 81.557377 | BT11: 84.081633 | BU11: 82.44898 | BV11: 84.897959 | BW11: 82.857143 | BX11: 82.786885 | BY11: 84.081633 | BZ11: 82.857143 | CA11: 82.44898 | CB11: 83.265306 | CC11: 81.557377 | CD11: 82.040816 | CE11: 82.44898 | CF11: 83.265306 | CG11: 82.857143 | CH11: 80.327869 | CI11: 83.265306 | CJ11: 82.040816 | CK11: 82.857143 | CL11: 82.857143 | CM11: 81.557377 | CN11: 82.857143 | CO11: 82.857143 | CP11: 82.44898 | CQ11: 82.857143
A12: 89.52381 | B12: 91.428571 | C12: 91.509434 | D12: 91.509434 | E12: 91.509434 | F12: 89.52381 | G12: 91.428571 | H12: 91.509434 | I12: 91.509434 | J12: 91.509434 | K12: 89.52381 | L12: 91.428571 | M12: 91.509434 | N12: 91.509434 | O12: 91.509434 | P12: 89.52381 | Q12: 91.428571 | R12: 91.509434 | S12: 91.509434 | T12: 91.509434 | U12: 89.52381 | V12: 91.428571 | W12: 91.509434 | X12: 91.509434 | Y12: 91.509434 | Z12: 89.52381 | AA12: 91.428571 | AB12: 91.509434 | AC12: 91.509434 | AD12: 92.45283 | AE12: 89.52381 | AF12: 91.428571 | AG12: 91.509434 | AH12: 91.509434 | AI12: 91.509434 | AJ12: 89.52381 | AK12: 91.428571 | AL12: 91.509434 | AM12: 91.509434 | AN12: 91.509434 | AO12: 89.52381 | AP12: 91.428571 | AQ12: 91.509434 | AR12: 91.509434 | AS12: 91.509434 | AT12: 89.52381 | AU12: 91.428571 | AV12: 91.509434 | AW12: 91.509434 | AX12: 91.509434 | AY12: 89.52381 | AZ12: 91.428571 | BA12: 91.509434 | BB12: 91.509434 | BC12: 91.509434 | BD12: 89.52381 | BE12: 91.428571 | BF12: 91.509434 | BG12: 91.509434 | BH12: 91.509434 | BI12: 89.52381 | BJ12: 91.428571 | BK12: 91.509434 | BL12: 91.509434 | BM12: 91.509434 | BN12: 89.52381 | BO12: 91.428571 | BP12: 91.509434 | BQ12: 91.509434 | BR12: 91.509434 | BS12: 89.52381 | BT12: 91.428571 | BU12: 91.509434 | BV12: 91.509434 | BW12: 91.509434 | BX12: 89.52381 | BY12: 91.428571 | BZ12: 91.509434 | CA12: 91.509434 | CB12: 91.509434 | CC12: 89.52381 | CD12: 91.428571 | CE12: 91.509434 | CF12: 91.509434 | CG12: 91.509434 | CH12: 89.52381 | CI12: 91.428571 | CJ12: 91.509434 | CK12: 91.509434 | CL12: 91.509434 | CM12: 89.52381 | CN12: 91.428571 | CO12: 91.509434 | CP12: 91.509434 | CQ12: 91.509434
A13: 99.285714 | B13: 99.644128 | C13: 99.644128 | D13: 99.288256 | E13: 99.288256 | F13: 99.285714 | G13: 98.932384 | H13: 99.288256 | I13: 98.932384 | J13: 98.576512 | K13: 99.285714 | L13: 99.288256 | M13: 99.288256 | N13: 98.932384 | O13: 99.288256 | P13: 99.285714 | Q13: 99.644128 | R13: 100 | S13: 98.932384 | T13: 98.932384 | U13: 98.571429 | V13: 99.644128 | W13: 99.288256 | X13: 98.932384 | Y13: 98.932384 | Z13: 99.285714 | AA13: 98.576512 | AB13: 98.932384 | AC13: 98.576512 | AD13: 98.576512 | AE13: 99.285714 | AF13: 99.288256 | AG13: 100 | AH13: 99.288256 | AI13: 98.932384 | AJ13: 98.571429 | AK13: 99.644128 | AL13: 98.932384 | AM13: 98.220641 | AN13: 98.220641 | AO13: 98.571429 | AP13: 99.288256 | AQ13: 98.576512 | AR13: 98.932384 | AS13: 98.220641 | AT13: 99.285714 | AU13: 98.932384 | AV13: 98.576512 | AW13: 98.576512 | AX13: 98.932384 | AY13: 99.285714 | AZ13: 99.288256 | BA13: 99.644128 | BB13: 99.288256 | BC13: 98.576512 | BD13: 98.928571 | BE13: 99.644128 | BF13: 98.576512 | BG13: 98.576512 | BH13: 98.576512 | BI13: 99.285714 | BJ13: 99.644128 | BK13: 100 | BL13: 99.644128 | BM13: 98.932384 | BN13: 99.285714 | BO13: 99.644128 | BP13: 99.288256 | BQ13: 99.644128 | BR13: 98.932384 | BS13: 98.571429 | BT13: 98.576512 | BU13: 98.576512 | BV13: 98.932384 | BW13: 98.576512 | BX13: 99.285714 | BY13: 99.644128 | BZ13: 100 | CA13: 99.288256 | CB13: 98.932384 | CC13: 99.285714 | CD13: 99.644128 | CE13: 100 | CF13: 99.288256 | CG13: 98.932384 | CH13: 99.285714 | CI13: 98.932384 | CJ13: 98.576512 | CK13: 98.576512 | CL13: 98.932384 | CM13: 98.928571 | CN13: 99.644128 | CO13: 100 | CP13: 99.644128 | CQ13: 98.576512
... A34: 62.005055 | B34: 63.689975 | C34: 62.847515 | D34: 62.931761 | E34: 62.037037 | F34: 61.162595 | G34: 63.100253 | H34: 64.026959 | I34: 64.026959 | J34: 62.457912 | K34: 61.078349 | L34: 63.437237 | M34: 63.605729 | N34: 63.774221 | O34: 60.26936 | P34: 61.583825 | Q34: 63.437237 | R34: 63.437237 | S34: 63.942713 | T34: 60.942761 | U34: 60.488627 | V34: 63.689975 | W34: 63.016007 | X34: 63.016007 | Y34: 59.511785 | Z34: 62.594777 | AA34: 64.111205 | AB34: 63.942713 | AC34: 63.016007 | AD34: 62.289562 | AE34: 61.752317 | AF34: 65.206403 | AG34: 63.774221 | AH34: 63.942713 | AI34: 62.710438 | AJ34: 62.426285 | AK34: 64.111205 | AL34: 62.763269 | AM34: 62.173547 | AN34: 61.616162 | AO34: 60.657119 | AP34: 63.016007 | AQ34: 63.016007 | AR34: 63.352991 | AS34: 61.616162 | AT34: 62.594777 | AU34: 65.374895 | AV34: 65.206403 | AW34: 62.594777 | AX34: 63.888889 | AY34: 62.426285 | AZ34: 63.605729 | BA34: 65.037911 | BB34: 63.605729 | BC34: 61.868687 | BD34: 62.510531 | BE34: 63.100253 | BF34: 63.605729 | BG34: 63.689975 | BH34: 60.26936 | BI34: 61.920809 | BJ34: 64.616681 | BK34: 64.532435 | BL34: 65.122157 | BM34: 62.710438 | BN34: 62.426285 | BO34: 63.774221 | BP34: 62.594777 | BQ34: 62.931761 | BR34: 61.784512 | BS34: 60.067397 | BT34: 62.510531 | BU34: 63.184499 | BV34: 62.931761 | BW34: 61.026936 | BX34: 62.847515 | BY34: 63.774221 | BZ34: 64.953665 | CA34: 63.605729 | CB34: 62.205387 | CC34: 62.679023 | CD34: 64.026959 | CE34: 65.627633 | CF34: 63.689975 | CG34: 63.804714 | CH34: 62.594777 | CI34: 65.374895 | CJ34: 65.206403 | CK34: 62.594777 | CL34: 63.888889 | CM34: 62.257793 | CN34: 64.195451 | CO34: 64.616681 | CP34: 63.521483 | CQ34: 63.047138

Sheet Test
A1: resultsPro/1_1 | B1: resultsPro/1_1 | C1: resultsPro/1_1 | D1: resultsPro/1_1 | E1: resultsPro/1_1 | F1: resultsPro/2_1 | G1: resultsPro/2_1 | H1: resultsPro/2_1 | I1: resultsPro/2_1 | J1: resultsPro/2_1 | K1: resultsPro/3_1 | L1: resultsPro/3_1 | M1: resultsPro/3_1 | N1: resultsPro/3_1 | O1: resultsPro/3_1 | P1: resultsPro/4_1 | Q1: resultsPro/4_1 | R1: resultsPro/4_1 | S1: resultsPro/4_1 | T1: resultsPro/4_1 | U1: resultsPro/5_1 | V1: resultsPro/5_1 | W1: resultsPro/5_1 | X1: resultsPro/5_1 | Y1: resultsPro/5_1 | Z1: resultsPro/6_1 | AA1: resultsPro/6_1 | AB1: resultsPro/6_1 | AC1: resultsPro/6_1 | AD1: resultsPro/6_1 | AE1: resultsPro/7_1 | AF1: resultsPro/7_1 | AG1: resultsPro/7_1 | AH1: resultsPro/7_1 | AI1: resultsPro/7_1 | AJ1: resultsPro/8_1 | AK1: resultsPro/8_1 | AL1: resultsPro/8_1 | AM1: resultsPro/8_1 | AN1: resultsPro/8_1 | AO1: resultsPro/9_1 | AP1: resultsPro/9_1 | AQ1: resultsPro/9_1 | AR1: resultsPro/9_1 | AS1: resultsPro/9_1 | AT1: resultsPro/10_1 | AU1: resultsPro/10_1 | AV1: resultsPro/10_1 | AW1: resultsPro/10_1 | AX1: resultsPro/10_1 | AY1: resultsPro/11_1 | AZ1: resultsPro/11_1 | BA1: resultsPro/11_1 | BB1: resultsPro/11_1 | BC1: resultsPro/11_1 | BD1: resultsPro/12_1 | BE1: resultsPro/12_1 | BF1: resultsPro/12_1 | BG1: resultsPro/12_1 | BH1: resultsPro/12_1 | BI1: resultsPro/13_1 | BJ1: resultsPro/13_1 | BK1: resultsPro/13_1 | BL1: resultsPro/13_1 | BM1: resultsPro/13_1 | BN1: resultsPro/14_1 | BO1: resultsPro/14_1 | BP1: resultsPro/14_1 | BQ1: resultsPro/14_1 | BR1: resultsPro/14_1 | BS1: resultsPro/15_1 | BT1: resultsPro/15_1 | BU1: resultsPro/15_1 | BV1: resultsPro/15_1 | BW1: resultsPro/15_1 | BX1: resultsPro/16_1 | BY1: resultsPro/16_1 | BZ1: resultsPro/16_1 | CA1: resultsPro/16_1 | CB1: resultsPro/16_1 | CC1: resultsPro/17_1 | CD1: resultsPro/17_1 | CE1: resultsPro/17_1 | CF1: resultsPro/17_1 | CG1: resultsPro/17_1 | CH1: resultsPro/18_1 | CI1: resultsPro/18_1 | CJ1: resultsPro/18_1 | CK1: resultsPro/18_1 | CL1: resultsPro/18_1 | CM1: resultsPro/19_1 | CN1: resultsPro/19_1 | CO1: resultsPro/19_1 | CP1: resultsPro/19_1 | CQ1: resultsPro/19_1
A2: 90.909091 | B2: 80.952381 | C2: 90.47619 | D2: 95.238095 | E2: 80.952381 | F2: 86.363636 | G2: 85.714286 | H2: 85.714286 | I2: 90.47619 | J2: 85.714286 | K2: 86.363636 | L2: 76.190476 | M2: 85.714286 | N2: 85.714286 | O2: 76.190476 | P2: 81.818182 | Q2: 71.428571 | R2: 85.714286 | S2: 95.238095 | T2: 85.714286 | U2: 90.909091 | V2: 80.952381 | W2: 90.47619 | X2: 90.47619 | Y2: 85.714286 | Z2: 81.818182 | AA2: 76.190476 | AB2: 85.714286 | AC2: 90.47619 | AD2: 80.952381 | AE2: 81.818182 | AF2: 76.190476 | AG2: 85.714286 | AH2: 90.47619 | AI2: 85.714286 | AJ2: 81.818182 | AK2: 80.952381 | AL2: 90.47619 | AM2: 90.47619 | AN2: 76.190476 | AO2: 86.363636 | AP2: 76.190476 | AQ2: 85.714286 | AR2: 95.238095 | AS2: 76.190476 | AT2: 81.818182 | AU2: 80.952381 | AV2: 90.47619 | AW2: 90.47619 | AX2: 80.952381 | AY2: 81.818182 | AZ2: 61.904762 | BA2: 85.714286 | BB2: 90.47619 | BC2: 80.952381 | BD2: 86.363636 | BE2: 76.190476 | BF2: 95.238095 | BG2: 90.47619 | BH2: 85.714286 | BI2: 81.818182 | BJ2: 71.428571 | BK2: 90.47619 | BL2: 90.47619 | BM2: 85.714286 | BN2: 81.818182 | BO2: 76.190476 | BP2: 85.714286 | BQ2: 90.47619 | BR2: 85.714286 | BS2: 81.818182 | BT2: 80.952381 | BU2: 76.190476 | BV2: 90.47619 | BW2: 80.952381 | BX2: 81.818182 | BY2: 71.428571 | BZ2: 85.714286 | CA2: 90.47619 | CB2: 85.714286 | CC2: 81.818182 | CD2: 66.666667 | CE2: 90.47619 | CF2: 90.47619 | CG2: 85.714286 | CH2: 81.818182 | CI2: 80.952381 | CJ2: 90.47619 | CK2: 90.47619 | CL2: 80.952381 | CM2: 77.272727 | CN2: 76.190476 | CO2: 85.714286 | CP2: 90.47619 | CQ2: 80.952381
A3: 80 | B3: 78.4 | C3: 81.6 | D3: 84 | E3: 83.2 | F3: 84.8 | G3: 79.2 | H3: 84.8 | I3: 82.4 | J3: 82.4 | K3: 72 | L3: 76 | M3: 81.6 | N3: 83.2 | O3: 76 | P3: 83.2 | Q3: 82.4 | R3: 88 | S3: 84.8 | T3: 83.2 | U3: 84 | V3: 81.6 | W3: 80 | X3: 82.4 | Y3: 85.6 | Z3: 88 | AA3: 88 | AB3: 89.6 | AC3: 88 | AD3: 88.8 | AE3: 81.6 | AF3: 84.8 | AG3: 85.6 | AH3: 82.4 | AI3: 80 | AJ3: 80.8 | AK3: 81.6 | AL3: 85.6 | AM3: 80.8 | AN3: 80.8 | AO3: 86.4 | AP3: 83.2 | AQ3: 87.2 | AR3: 86.4 | AS3: 79.2 | AT3: 80 | AU3: 89.6 | AV3: 89.6 | AW3: 80 | AX3: 82.4 | AY3: 84 | AZ3: 88 | BA3: 86.4 | BB3: 86.4 | BC3: 87.2 | BD3: 72.8 | BE3: 75.2 | BF3: 80 | BG3: 80.8 | BH3: 81.6 | BI3: 80.8 | BJ3: 88.8 | BK3: 84.8 | BL3: 84 | BM3: 87.2 | BN3: 80.8 | BO3: 83.2 | BP3: 85.6 | BQ3: 85.6 | BR3: 84 | BS3: 73.6 | BT3: 76 | BU3: 78.4 | BV3: 77.6 | BW3: 77.6 | BX3: 84.8 | BY3: 85.6 | BZ3: 86.4 | CA3: 88 | CB3: 84 | CC3: 81.6 | CD3: 87.2 | CE3: 88.8 | CF3: 87.2 | CG3: 85.6 | CH3: 80 | CI3: 89.6 | CJ3: 89.6 | CK3: 80 | CL3: 82.4 | CM3: 85.6 | CN3: 88 | CO3: 87.2 | CP3: 85.6 | CQ3: 86.4
A4: 84.056604 | B4: 83.207547 | C4: 84.716981 | D4: 84.433962 | E4: 84.150943 | F4: 86.320755 | G4: 84.433962 | H4: 86.037736 | I4: 84.245283 | J4: 86.981132 | K4: 84.622642 | L4: 84.90566 | M4: 83.396226 | N4: 84.622642 | O4: 86.132075 | P4: 82.54717 | Q4: 85 | R4: 87.075472 | S4: 87.075472 | T4: 86.320755 | U4: 86.981132 | V4: 84.622642 | W4: 86.981132 | X4: 85.849057 | Y4: 86.037736 | Z4: 81.792453 | AA4: 85 | AB4: 83.962264 | AC4: 83.113208 | AD4: 84.528302 | AE4: 85.566038 | AF4: 84.528302 | AG4: 85.849057 | AH4: 84.150943 | AI4: 84.90566 | AJ4: 83.962264 | AK4: 84.811321 | AL4: 85 | AM4: 86.509434 | AN4: 85.566038 | AO4: 83.207547 | AP4: 83.018868 | AQ4: 85.283019 | AR4: 85 | AS4: 85.283019 | AT4: 84.433962 | AU4: 83.396226 | AV4: 85.09434 | AW4: 83.301887 | AX4: 85 | AY4: 83.584906 | AZ4: 81.603774 | BA4: 84.150943 | BB4: 87.075472 | BC4: 86.132075 | BD4: 85.660377 | BE4: 84.528302 | BF4: 85.849057 | BG4: 86.981132 | BH4: 86.226415 | BI4: 85.377358 | BJ4: 83.962264 | BK4: 84.528302 | BL4: 86.886792 | BM4: 86.698113 | BN4: 86.509434 | BO4: 84.716981 | BP4: 86.509434 | BQ4: 85.566038 | BR4: 86.981132 | BS4: 84.150943 | BT4: 83.018868 | BU4: 82.54717 | BV4: 83.867925 | BW4: 85.660377 | BX4: 84.056604 | BY4: 83.396226 | BZ4: 86.226415 | CA4: 85.471698 | CB4: 85.283019 | CC4: 86.415094 | CD4: 82.735849 | CE4: 87.075472 | CF4: 86.132075 | CG4: 84.811321 | CH4: 84.433962 | CI4: 83.396226 | CJ4: 85.09434 | CK4: 83.301887 | CL4: 85 | CM4: 82.735849 | CN4: 83.207547 | CO4: 86.603774 | CP4: 84.150943 | CQ4: 87.075472
A5: 69.333333 | B5: 72.222222 | C5: 63.513514 | D5: 71.830986 | E5: 69.863014 | F5: 69.333333 | G5: 73.611111 | H5: 66.216216 | I5: 70.422535 | J5: 75.342466 | K5: 68 | L5: 62.5 | M5: 72.972973 | N5: 64.788732 | O5: 69.863014 | P5: 64 | Q5: 69.444444 | R5: 67.567568 | S5: 76.056338 | T5: 68.493151 | U5: 65.333333 | V5: 72.222222 | W5: 67.567568 | X5: 67.605634 | Y5: 71.232877 | Z5: 68 | AA5: 69.444444 | AB5: 70.27027 | AC5: 74.647887 | AD5: 63.013699 | AE5: 62.666667 | AF5: 69.444444 | AG5: 68.918919 | AH5: 73.239437 | AI5: 68.493151 | AJ5: 62.666667 | AK5: 63.888889 | AL5: 68.918919 | AM5: 69.014085 | AN5: 65.753425 | AO5: 68 | AP5: 72.222222 | AQ5: 74.324324 | AR5: 69.014085 | AS5: 67.123288 | AT5: 72 | AU5: 77.777778 | AV5: 68.918919 | AW5: 74.647887 | AX5: 69.863014 | AY5: 65.333333 | AZ5: 72.222222 | BA5: 64.864865 | BB5: 74.647887 | BC5: 67.123288 | BD5: 66.666667 | BE5: 69.444444 | BF5: 67.567568 | BG5: 69.014085 | BH5: 69.863014 | BI5: 64 | BJ5: 75 | BK5: 64.864865 | BL5: 77.464789 | BM5: 63.013699 | BN5: 69.333333 | BO5: 70.833333 | BP5: 71.621622 | BQ5: 67.605634 | BR5: 65.753425 | BS5: 66.666667 | BT5: 59.722222 | BU5: 70.27027 | BV5: 70.422535 | BW5: 69.863014 | BX5: 62.666667 | BY5: 76.388889 | BZ5: 67.567568 | CA5: 76.056338 | CB5: 65.753425 | CC5: 66.666667 | CD5: 69.444444 | CE5: 62.162162 | CF5: 70.422535 | CG5: 72.60274 | CH5: 72 | CI5: 77.777778 | CJ5: 68.918919 | CK5: 74.647887 | CL5: 69.863014 | CM5: 64 | CN5: 66.666667 | CO5: 63.513514 | CP5: 74.647887 | CQ5: 72.60274
A6: 69.565217 | B6: 63.768116 | C6: 65.217391 | D6: 66.666667 | E6: 68.115942 | F6: 63.768116 | G6: 65.217391 | H6: 65.217391 | I6: 52.173913 | J6: 68.115942 | K6: 60.869565 | L6: 63.768116 | M6: 66.666667 | N6: 62.318841 | O6: 71.014493 | P6: 62.318841 | Q6: 62.318841 | R6: 62.318841 | S6: 62.318841 | T6: 72.463768 | U6: 65.217391 | V6: 65.217391 | W6: 68.115942 | X6: 62.318841 | Y6: 71.014493 | Z6: 53.623188 | AA6: 62.318841 | AB6: 63.768116 | AC6: 66.666667 | AD6: 71.014493 | AE6: 65.217391 | AF6: 65.217391 | AG6: 59.42029 | AH6: 72.463768 | AI6: 73.913043 | AJ6: 66.666667 | AK6: 62.318841 | AL6: 62.318841 | AM6: 63.768116 | AN6: 75.362319 | AO6: 62.318841 | AP6: 66.666667 | AQ6: 60.869565 | AR6: 62.318841 | AS6: 75.362319 | AT6: 62.318841 | AU6: 57.971014 | AV6: 57.971014 | AW6: 65.217391 | AX6: 76.811594 | AY6: 62.318841 | AZ6: 62.318841 | BA6: 55.072464 | BB6: 66.666667 | BC6: 71.014493 | BD6: 62.318841 | BE6: 63.768116 | BF6: 65.217391 | BG6: 62.318841 | BH6: 72.463768 | BI6: 62.318841 | BJ6: 65.217391 | BK6: 66.666667 | BL6: 60.869565 | BM6: 73.913043 | BN6: 62.318841 | BO6: 68.115942 | BP6: 66.666667 | BQ6: 65.217391 | BR6: 72.463768 | BS6: 50.724638 | BT6: 62.318841 | BU6: 60.869565 | BV6: 55.072464 | BW6: 75.362319 | BX6: 63.768116 | BY6: 65.217391 | BZ6: 65.217391 | CA6: 57.971014 | CB6: 73.913043 | CC6: 65.217391 | CD6: 65.217391 | CE6: 60.869565 | CF6: 63.768116 | CG6: 71.014493 | CH6: 62.318841 | CI6: 57.971014 | CJ6: 57.971014 | CK6: 65.217391 | CL6: 76.811594 | CM6: 71.014493 | CN6: 69.565217 | CO6: 56.521739 | CP6: 59.42029 | CQ6: 71.014493
A7: 60 | B7: 53.333333 | C7: 64.40678 | D7: 52.542373 | E7: 57.627119 | F7: 60 | G7: 58.333333 | H7: 61.016949 | I7: 52.542373 | J7: 49.152542 | K7: 61.666667 | L7: 56.666667 | M7: 55.932203 | N7: 50.847458 | O7: 50.847458 | P7: 56.666667 | Q7: 56.666667 | R7: 50.847458 | S7: 47.457627 | T7: 59.322034 | U7: 63.333333 | V7: 53.333333 | W7: 55.932203 | X7: 52.542373 | Y7: 59.322034 | Z7: 58.333333 | AA7: 45 | AB7: 57.627119 | AC7: 61.016949 | AD7: 64.40678 | AE7: 61.666667 | AF7: 53.333333 | AG7: 55.932203 | AH7: 54.237288 | AI7: 59.322034 | AJ7: 58.333333 | AK7: 46.666667 | AL7: 57.627119 | AM7: 49.152542 | AN7: 57.627119 | AO7: 61.666667 | AP7: 48.333333 | AQ7: 55.932203 | AR7: 44.067797 | AS7: 54.237288 | AT7: 65 | AU7: 53.333333 | AV7: 59.322034 | AW7: 52.542373 | AX7: 54.237288 | AY7: 60 | AZ7: 46.666667 | BA7: 50.847458 | BB7: 57.627119 | BC7: 57.627119 | BD7: 61.666667 | BE7: 51.666667 | BF7: 55.932203 | BG7: 52.542373 | BH7: 62.711864 | BI7: 65 | BJ7: 53.333333 | BK7: 59.322034 | BL7: 52.542373 | BM7: 64.40678 | BN7: 60 | BO7: 53.333333 | BP7: 57.627119 | BQ7: 50.847458 | BR7: 62.711864 | BS7: 66.666667 | BT7: 55 | BU7: 50.847458 | BV7: 54.237288 | BW7: 59.322034 | BX7: 61.666667 | BY7: 51.666667 | BZ7: 50.847458 | CA7: 49.152542 | CB7: 59.322034 | CC7: 61.666667 | CD7: 46.666667 | CE7: 59.322034 | CF7: 45.762712 | CG7: 54.237288 | CH7: 65 | CI7: 53.333333 | CJ7: 59.322034 | CK7: 52.542373 | CL7: 54.237288 | CM7: 63.333333 | CN7: 55 | CO7: 62.711864 | CP7: 49.152542 | CQ7: 55.932203
A8: 55.254237 | B8: 47.118644 | C8: 52.881356 | D8: 53.741497 | E8: 48.29932 | F8: 50.169492 | G8: 49.491525 | H8: 52.20339 | I8: 47.278912 | J8: 46.938776 | K8: 49.830508 | L8: 48.135593 | M8: 50.169492 | N8: 46.598639 | O8: 48.639456 | P8: 52.542373 | Q8: 47.79661 | R8: 51.864407 | S8: 55.442177 | T8: 48.979592 | U8: 58.305085 | V8: 43.389831 | W8: 48.135593 | X8: 45.918367 | Y8: 46.938776 | Z8: 53.898305 | AA8: 51.525424 | AB8: 51.186441 | AC8: 53.741497 | AD8: 52.040816 | AE8: 56.271186 | AF8: 49.830508 | AG8: 48.135593 | AH8: 51.70068 | AI8: 50.340136 | AJ8: 51.525424 | AK8: 49.830508 | AL8: 53.220339 | AM8: 51.70068 | AN8: 52.040816 | AO8: 53.220339 | AP8: 40.677966 | AQ8: 52.881356 | AR8: 51.020408 | AS8: 52.380952 | AT8: 53.220339 | AU8: 48.474576 | AV8: 51.525424 | AW8: 51.70068 | AX8: 52.380952 | AY8: 55.59322 | AZ8: 51.525424 | BA8: 50.169492 | BB8: 56.122449 | BC8: 50.680272 | BD8: 50.847458 | BE8: 50.847458 | BF8: 49.152542 | BG8: 47.619048 | BH8: 48.639456 | BI8: 55.932203 | BJ8: 43.728814 | BK8: 51.864407 | BL8: 53.401361 | BM8: 50 | BN8: 55.254237 | BO8: 46.779661 | BP8: 55.254237 | BQ8: 52.040816 | BR8: 50.340136 | BS8: 51.525424 | BT8: 41.355932 | BU8: 47.118644 | BV8: 47.278912 | BW8: 43.877551 | BX8: 55.59322 | BY8: 52.20339 | BZ8: 52.881356 | CA8: 52.721088 | CB8: 50.340136 | CC8: 54.915254 | CD8: 51.864407 | CE8: 54.576271 | CF8: 55.782313 | CG8: 51.70068 | CH8: 53.220339 | CI8: 48.474576 | CJ8: 51.525424 | CK8: 51.70068 | CL8: 52.380952 | CM8: 56.610169 | CN8: 50.508475 | CO8: 51.864407 | CP8: 55.102041 | CQ8: 53.401361
A9: 67.647059 | B9: 77.61194 | C9: 73.134328 | D9: 80.597015 | E9: 83.58209 | F9: 69.117647 | G9: 82.089552 | H9: 74.626866 | I9: 76.119403 | J9: 82.089552 | K9: 70.588235 | L9: 82.089552 | M9: 74.626866 | N9: 73.134328 | O9: 85.074627 | P9: 69.117647 | Q9: 77.61194 | R9: 70.149254 | S9: 76.119403 | T9: 76.119403 | U9: 69.117647 | V9: 79.104478 | W9: 71.641791 | X9: 79.104478 | Y9: 88.059701 | Z9: 73.529412 | AA9: 79.104478 | AB9: 77.61194 | AC9: 82.089552 | AD9: 85.074627 | AE9: 75 | AF9: 77.61194 | AG9: 73.134328 | AH9: 79.104478 | AI9: 83.58209 | AJ9: 70.588235 | AK9: 76.119403 | AL9: 71.641791 | AM9: 77.61194 | AN9: 83.58209 | AO9: 73.529412 | AP9: 77.61194 | AQ9: 74.626866 | AR9: 77.61194 | AS9: 83.58209 | AT9: 75 | AU9: 82.089552 | AV9: 68.656716 | AW9: 77.61194 | AX9: 88.059701 | AY9: 67.647059 | AZ9: 70.149254 | BA9: 76.119403 | BB9: 76.119403 | BC9: 85.074627 | BD9: 69.117647 | BE9: 77.61194 | BF9: 71.641791 | BG9: 68.656716 | BH9: 85.074627 | BI9: 73.529412 | BJ9: 74.626866 | BK9: 77.61194 | BL9: 76.119403 | BM9: 83.58209 | BN9: 75 | BO9: 83.58209 | BP9: 76.119403 | BQ9: 76.119403 | BR9: 82.089552 | BS9: 69.117647 | BT9: 76.119403 | BU9: 74.626866 | BV9: 71.641791 | BW9: 74.626866 | BX9: 70.588235 | BY9: 80.597015 | BZ9: 71.641791 | CA9: 73.134328 | CB9: 88.059701 | CC9: 75 | CD9: 82.089552 | CE9: 70.149254 | CF9: 80.597015 | CG9: 88.059701 | CH9: 75 | CI9: 82.089552 | CJ9: 68.656716 | CK9: 77.61194 | CL9: 88.059701 | CM9: 76.470588 | CN9: 83.58209 | CO9: 71.641791 | CP9: 76.119403 | CQ9: 83.58209
A10: 62.790698 | B10: 60.465116 | C10: 60.465116 | D10: 65.116279 | E10: 64.285714 | F10: 60.465116 | G10: 55.813953 | H10: 62.790698 | I10: 67.44186 | J10: 69.047619 | K10: 67.44186 | L10: 62.790698 | M10: 60.465116 | N10: 60.465116 | O10: 71.428571 | P10: 67.44186 | Q10: 65.116279 | R10: 69.767442 | S10: 69.767442 | T10: 64.285714 | U10: 60.465116 | V10: 60.465116 | W10: 55.813953 | X10: 62.790698 | Y10: 64.285714 | Z10: 60.465116 | AA10: 62.790698 | AB10: 67.44186 | AC10: 69.767442 | AD10: 69.047619 | AE10: 62.790698 | AF10: 55.813953 | AG10: 65.116279 | AH10: 67.44186 | AI10: 59.52381 | AJ10: 60.465116 | AK10: 62.790698 | AL10: 65.116279 | AM10: 62.790698 | AN10: 61.904762 | AO10: 55.813953 | AP10: 58.139535 | AQ10: 58.139535 | AR10: 65.116279 | AS10: 64.285714 | AT10: 62.790698 | AU10: 58.139535 | AV10: 62.790698 | AW10: 67.44186 | AX10: 73.809524 | AY10: 67.44186 | AZ10: 58.139535 | BA10: 65.116279 | BB10: 69.767442 | BC10: 66.666667 | BD10: 72.093023 | BE10: 58.139535 | BF10: 58.139535 | BG10: 69.767442 | BH10: 64.285714 | BI10: 67.44186 | BJ10: 60.465116 | BK10: 58.139535 | BL10: 67.44186 | BM10: 61.904762 | BN10: 69.767442 | BO10: 58.139535 | BP10: 67.44186 | BQ10: 69.767442 | BR10: 71.428571 | BS10: 58.139535 | BT10: 65.116279 | BU10: 65.116279 | BV10: 65.116279 | BW10: 64.285714 | BX10: 67.44186 | BY10: 60.465116 | BZ10: 55.813953 | CA10: 72.093023 | CB10: 66.666667 | CC10: 65.116279 | CD10: 58.139535 | CE10: 62.790698 | CF10: 69.767442 | CG10: 69.047619 | CH10: 62.790698 | CI10: 58.139535 | CJ10: 62.790698 | CK10: 67.44186 | CL10: 73.809524 | CM10: 58.139535 | CN10: 60.465116 | CO10: 60.465116 | CP10: 65.116279 | CQ10: 66.666667
A11: 77.419355 | B11: 70.491803 | C11: 72.131148 | D11: 67.213115 | E11: 77.04918 | F11: 75.806452 | G11: 68.852459 | H11: 73.770492 | I11: 68.852459 | J11: 73.770492 | K11: 75.806452 | L11: 67.213115 | M11: 68.852459 | N11: 75.409836 | O11: 75.409836 | P11: 80.645161 | Q11: 68.852459 | R11: 73.770492 | S11: 70.491803 | T11: 77.04918 | U11: 77.419355 | V11: 65.57377 | W11: 75.409836 | X11: 70.491803 | Y11: 75.409836 | Z11: 79.032258 | AA11: 67.213115 | AB11: 68.852459 | AC11: 65.57377 | AD11: 73.770492 | AE11: 77.419355 | AF11: 67.213115 | AG11: 72.131148 | AH11: 63.934426 | AI11: 77.04918 | AJ11: 77.419355 | AK11: 68.852459 | AL11: 73.770492 | AM11: 77.04918 | AN11: 73.770492 | AO11: 79.032258 | AP11: 67.213115 | AQ11: 77.04918 | AR11: 72.131148 | AS11: 77.04918 | AT11: 77.419355 | AU11: 67.213115 | AV11: 70.491803 | AW11: 77.04918 | AX11: 67.213115 | AY11: 77.419355 | AZ11: 70.491803 | BA11: 70.491803 | BB11: 70.491803 | BC11: 72.131148 | BD11: 82.258065 | BE11: 68.852459 | BF11: 70.491803 | BG11: 73.770492 | BH11: 73.770492 | BI11: 74.193548 | BJ11: 72.131148 | BK11: 70.491803 | BL11: 59.016393 | BM11: 73.770492 | BN11: 75.806452 | BO11: 70.491803 | BP11: 72.131148 | BQ11: 70.491803 | BR11: 72.131148 | BS11: 74.193548 | BT11: 67.213115 | BU11: 72.131148 | BV11: 70.491803 | BW11: 77.04918 | BX11: 77.419355 | BY11: 68.852459 | BZ11: 70.491803 | CA11: 68.852459 | CB11: 73.770492 | CC11: 77.419355 | CD11: 65.57377 | CE11: 77.04918 | CF11: 70.491803 | CG11: 70.491803 | CH11: 77.419355 | CI11: 67.213115 | CJ11: 70.491803 | CK11: 77.04918 | CL11: 67.213115 | CM11: 70.967742 | CN11: 67.213115 | CO11: 72.131148 | CP11: 68.852459 | CQ11: 70.491803
A12: 88.888889 | B12: 77.777778 | C12: 80.769231 | D12: 73.076923 | E12: 73.076923 | F12: 88.888889 | G12: 77.777778 | H12: 84.615385 | I12: 73.076923 | J12: 73.076923 | K12: 88.888889 | L12: 77.777778 | M12: 80.769231 | N12: 73.076923 | O12: 73.076923 | P12: 88.888889 | Q12: 77.777778 | R12: 80.769231 | S12: 73.076923 | T12: 73.076923 | U12: 88.888889 | V12: 77.777778 | W12: 80.769231 | X12: 73.076923 | Y12: 73.076923 | Z12: 88.888889 | AA12: 81.481481 | AB12: 80.769231 | AC12: 76.923077 | AD12: 76.923077 | AE12: 88.888889 | AF12: 77.777778 | AG12: 80.769231 | AH12: 73.076923 | AI12: 73.076923 | AJ12: 88.888889 | AK12: 77.777778 | AL12: 80.769231 | AM12: 73.076923 | AN12: 73.076923 | AO12: 88.888889 | AP12: 77.777778 | AQ12: 80.769231 | AR12: 73.076923 | AS12: 73.076923 | AT12: 88.888889 | AU12: 77.777778 | AV12: 80.769231 | AW12: 73.076923 | AX12: 73.076923 | AY12: 88.888889 | AZ12: 77.777778 | BA12: 80.769231 | BB12: 73.076923 | BC12: 73.076923 | BD12: 88.888889 | BE12: 77.777778 | BF12: 84.615385 | BG12: 73.076923 | BH12: 73.076923 | BI12: 88.888889 | BJ12: 77.777778 | BK12: 80.769231 | BL12: 73.076923 | BM12: 73.076923 | BN12: 88.888889 | BO12: 77.777778 | BP12: 80.769231 | BQ12: 73.076923 | BR12: 73.076923 | BS12: 85.185185 | BT12: 74.074074 | BU12: 84.615385 | BV12: 73.076923 | BW12: 80.769231 | BX12: 88.888889 | BY12: 77.777778 | BZ12: 80.769231 | CA12: 73.076923 | CB12: 73.076923 | CC12: 88.888889 | CD12: 77.777778 | CE12: 80.769231 | CF12: 73.076923 | CG12: 73.076923 | CH12: 88.888889 | CI12: 77.777778 | CJ12: 80.769231 | CK12: 73.076923 | CL12: 73.076923 | CM12: 88.888889 | CN12: 77.777778 | CO12: 80.769231 | CP12: 73.076923 | CQ12: 73.076923
A13: 85.915493 | B13: 88.571429 | C13: 85.714286 | D13: 92.857143 | E13: 85.714286 | F13: 77.464789 | G13: 88.571429 | H13: 87.142857 | I13: 95.714286 | J13: 87.142857 | K13: 83.098592 | L13: 91.428571 | M13: 87.142857 | N13: 94.285714 | O13: 91.428571 | P13: 76.056338 | Q13: 88.571429 | R13: 88.571429 | S13: 94.285714 | T13: 85.714286 | U13: 84.507042 | V13: 87.142857 | W13: 87.142857 | X13: 94.285714 | Y13: 84.285714 | Z13: 84.507042 | AA13: 91.428571 | AB13: 90 | AC13: 95.714286 | AD13: 88.571429 | AE13: 87.323944 | AF13: 88.571429 | AG13: 90 | AH13: 95.714286 | AI13: 87.142857 | AJ13: 78.873239 | AK13: 92.857143 | AL13: 87.142857 | AM13: 92.857143 | AN13: 87.142857 | AO13: 85.915493 | AP13: 90 | AQ13: 84.285714 | AR13: 94.285714 | AS13: 87.142857 | AT13: 85.915493 | AU13: 88.571429 | AV13: 90 | AW13: 95.714286 | AX13: 91.428571 | AY13: 85.915493 | AZ13: 92.857143 | BA13: 87.142857 | BB13: 95.714286 | BC13: 82.857143 | BD13: 81.690141 | BE13: 88.571429 | BF13: 85.714286 | BG13: 92.857143 | BH13: 90 | BI13: 87.323944 | BJ13: 88.571429 | BK13: 81.428571 | BL13: 92.857143 | BM13: 90 | BN13: 85.915493 | BO13: 91.428571 | BP13: 88.571429 | BQ13: 94.285714 | BR13: 88.571429 | BS13: 85.915493 | BT13: 90 | BU13: 85.714286 | BV13: 92.857143 | BW13: 88.571429 | BX13: 83.098592 | BY13: 91.428571 | BZ13: 88.571429 | CA13: 94.285714 | CB13: 88.571429 | CC13: 85.915493 | CD13: 82.857143 | CE13: 85.714286 | CF13: 97.142857 | CG13: 88.571429 | CH13: 85.915493 | CI13: 88.571429 | CJ13: 90 | CK13: 95.714286 | CL13: 91.428571 | CM13: 85.915493 | CN13: 88.571429 | CO13: 84.285714 | CP13: 94.285714 | CQ13: 87.142857
... A34: 59.93266 | B34: 56.902357 | C34: 52.525253 | D34: 55.218855 | E34: 56.756757 | F34: 57.575758 | G34: 58.585859 | H34: 54.208754 | I34: 57.912458 | J34: 57.432432 | K34: 58.922559 | L34: 58.585859 | M34: 56.565657 | N34: 59.259259 | O34: 59.459459 | P34: 58.585859 | Q34: 60.606061 | R34: 56.565657 | S34: 55.555556 | T34: 55.743243 | U34: 54.208754 | V34: 58.922559 | W34: 52.188552 | X34: 55.555556 | Y34: 57.77027 | Z34: 59.259259 | AA34: 59.259259 | AB34: 57.912458 | AC34: 56.228956 | AD34: 57.094595 | AE34: 59.59596 | AF34: 57.575758 | AG34: 55.218855 | AH34: 58.249158 | AI34: 57.77027 | AJ34: 56.902357 | AK34: 57.239057 | AL34: 58.249158 | AM34: 57.239057 | AN34: 56.081081 | AO34: 55.892256 | AP34: 55.892256 | AQ34: 53.872054 | AR34: 55.892256 | AS34: 52.027027 | AT34: 59.59596 | AU34: 57.912458 | AV34: 57.239057 | AW34: 56.228956 | AX34: 60.472973 | AY34: 58.922559 | AZ34: 56.565657 | BA34: 56.902357 | BB34: 55.218855 | BC34: 56.081081 | BD34: 53.872054 | BE34: 59.259259 | BF34: 54.208754 | BG34: 54.545455 | BH34: 59.459459 | BI34: 60.26936 | BJ34: 55.218855 | BK34: 55.555556 | BL34: 56.228956 | BM34: 56.756757 | BN34: 58.922559 | BO34: 57.239057 | BP34: 54.545455 | BQ34: 58.922559 | BR34: 57.77027 | BS34: 58.249158 | BT34: 56.565657 | BU34: 55.892256 | BV34: 56.228956 | BW34: 54.391892 | BX34: 57.239057 | BY34: 60.606061 | BZ34: 55.555556 | CA34: 60.26936 | CB34: 56.418919 | CC34: 59.59596 | CD34: 57.239057 | CE34: 56.228956 | CF34: 53.872054 | CG34: 57.094595 | CH34: 59.59596 | CI34: 57.912458 | CJ34: 57.239057 | CK34: 56.228956 | CL34: 60.472973 | CM34: 60.942761 | CN34: 56.565657 | CO34: 56.565657 | CP34: 55.892256 | CQ34: 57.094595

Sheet 1_1
A1: Dataset | B1: pt1 | C1: pt2 | D1: pt3 | E1: pt4 | F1: pt5 | G1: Mean | J1: Dataset | K1: pt1 | L1: pt2 | M1: pt3 | N1: pt4 | O1: pt5 | P1: Mean
A2: appendicitis | B2: =Training!A2 -> 96.428571 | C2: =Training!B2 -> 97.647059 | D2: =Training!C2 -> 97.647059 | E2: =Training!D2 -> 98.823529 | F2: =Training!E2 -> 96.470588 | G2: =AVERAGE(B2:F2) -> 97.403361 | J2: appendicitis | K2: =Test!A2 -> 90.909091 | L2: =Test!B2 -> 80.952381 | M2: =Test!C2 -> 90.47619 | N2: =Test!D2 -> 95.238095 | O2: =Test!E2 -> 80.952381 | P2: =AVERAGE(K2:O2) -> 87.705628
A3: balance | B3: =Training!A3 -> 86.4 | C3: =Training!B3 -> 82.6 | D3: =Training!C3 -> 86.8 | E3: =Training!D3 -> 86.4 | F3: =Training!E3 -> 86.4 | G3: =AVERAGE(B3:F3) -> 85.72 | J3: balance | K3: =Test!A3 -> 80 | L3: =Test!B3 -> 78.4 | M3: =Test!C3 -> 81.6 | N3: =Test!D3 -> 84 | O3: =Test!E3 -> 83.2 | P3: =AVERAGE(K3:O3) -> 81.44
A4: banana | B4: =Training!A4 -> 87.688679 | C4: =Training!B4 -> 86.627358 | D4: =Training!C4 -> 86.34434 | E4: =Training!D4 -> 84.316038 | F4: =Training!E4 -> 84.834906 | G4: =AVERAGE(B4:F4) -> 85.962264 | J4: banana | K4: =Test!A4 -> 84.056604 | L4: =Test!B4 -> 83.207547 | M4: =Test!C4 -> 84.716981 | N4: =Test!D4 -> 84.433962 | O4: =Test!E4 -> 84.150943 | P4: =AVERAGE(K4:O4) -> 84.113208
A5: bands | B5: =Training!A5 -> 90 | C5: =Training!B5 -> 88.054608 | D5: =Training!C5 -> 87.972509 | E5: =Training!D5 -> 91.496599 | F5: =Training!E5 -> 86.643836 | G5: =AVERAGE(B5:F5) -> 88.83351 | J5: bands | K5: =Test!A5 -> 69.333333 | L5: =Test!B5 -> 72.222222 | M5: =Test!C5 -> 63.513514 | N5: =Test!D5 -> 71.830986 | O5: =Test!E5 -> 69.863014 | P5: =AVERAGE(K5:O5) -> 69.352614
A6: bupa | B6: =Training!A6 -> 78.985507 | C6: =Training!B6 -> 81.884058 | D6: =Training!C6 -> 80.072464 | E6: =Training!D6 -> 80.072464 | F6: =Training!E6 -> 79.347826 | G6: =AVERAGE(B6:F6) -> 80.072464 | J6: bupa | K6: =Test!A6 -> 69.565217 | L6: =Test!B6 -> 63.768116 | M6: =Test!C6 -> 65.217391 | N6: =Test!D6 -> 66.666667 | O6: =Test!E6 -> 68.115942 | P6: =AVERAGE(K6:O6) -> 66.666667
A7: cleveland | B7: =Training!A7 -> 89.029536 | C7: =Training!B7 -> 91.139241 | D7: =Training!C7 -> 90.336134 | E7: =Training!D7 -> 89.915966 | F7: =Training!E7 -> 91.176471 | G7: =AVERAGE(B7:F7) -> 90.31947 | J7: cleveland | K7: =Test!A7 -> 60 | L7: =Test!B7 -> 53.333333 | M7: =Test!C7 -> 64.40678 | N7: =Test!D7 -> 52.542373 | O7: =Test!E7 -> 57.627119 | P7: =AVERAGE(K7:O7) -> 57.581921
A8: contraceptive | B8: =Training!A8 -> 60.441426 | C8: =Training!B8 -> 59.762309 | D8: =Training!C8 -> 61.544992 | E8: =Training!D8 -> 60.729432 | F8: =Training!E8 -> 60.050891 | G8: =AVERAGE(B8:F8) -> 60.50581 | J8: contraceptive | K8: =Test!A8 -> 55.254237 | L8: =Test!B8 -> 47.118644 | M8: =Test!C8 -> 52.881356 | N8: =Test!D8 -> 53.741497 | O8: =Test!E8 -> 48.29932 | P8: =AVERAGE(K8:O8) -> 51.459011
A9: ecoli | B9: =Training!A9 -> 88.80597 | C9: =Training!B9 -> 90.334572 | D9: =Training!C9 -> 90.334572 | E9: =Training!D9 -> 86.988848 | F9: =Training!E9 -> 91.821561 | G9: =AVERAGE(B9:F9) -> 89.657105 | J9: ecoli | K9: =Test!A9 -> 67.647059 | L9: =Test!B9 -> 77.61194 | M9: =Test!C9 -> 73.134328 | N9: =Test!D9 -> 80.597015 | O9: =Test!E9 -> 83.58209 | P9: =AVERAGE(K9:O9) -> 76.514486
A10: glass | B10: =Training!A10 -> 81.28655 | C10: =Training!B10 -> 86.549708 | D10: =Training!C10 -> 85.380117 | E10: =Training!D10 -> 80.701754 | F10: =Training!E10 -> 83.139535 | G10: =AVERAGE(B10:F10) -> 83.411533 | J10: glass | K10: =Test!A10 -> 62.790698 | L10: =Test!B10 -> 60.465116 | M10: =Test!C10 -> 60.465116 | N10: =Test!D10 -> 65.116279 | O10: =Test!E10 -> 64.285714 | P10: =AVERAGE(K10:O10) -> 62.624585
A11: haberman | B11: =Training!A11 -> 83.196721 | C11: =Training!B11 -> 82.857143 | D11: =Training!C11 -> 82.857143 | E11: =Training!D11 -> 84.897959 | F11: =Training!E11 -> 83.265306 | G11: =AVERAGE(B11:F11) -> 83.414854 | J11: haberman | K11: =Test!A11 -> 77.419355 | L11: =Test!B11 -> 70.491803 | M11: =Test!C11 -> 72.131148 | N11: =Test!D11 -> 67.213115 | O11: =Test!E11 -> 77.04918 | P11: =AVERAGE(K11:O11) -> 72.86092
A12: hayes-roth | B12: =Training!A12 -> 89.52381 | C12: =Training!B12 -> 91.428571 | D12: =Training!C12 -> 91.509434 | E12: =Training!D12 -> 91.509434 | F12: =Training!E12 -> 91.509434 | G12: =AVERAGE(B12:F12) -> 91.096137 | J12: hayes-roth | K12: =Test!A12 -> 88.888889 | L12: =Test!B12 -> 77.777778 | M12: =Test!C12 -> 80.769231 | N12: =Test!D12 -> 73.076923 | O12: =Test!E12 -> 73.076923 | P12: =AVERAGE(K12:O12) -> 78.717949
A13: ion | B13: =Training!A13 -> 99.285714 | C13: =Training!B13 -> 99.644128 | D13: =Training!C13 -> 99.644128 | E13: =Training!D13 -> 99.288256 | F13: =Training!E13 -> 99.288256 | G13: =AVERAGE(B13:F13) -> 99.430097 | J13: ion | K13: =Test!A13 -> 85.915493 | L13: =Test!B13 -> 88.571429 | M13: =Test!C13 -> 85.714286 | N13: =Test!D13 -> 92.857143 | O13: =Test!E13 -> 85.714286 | P13: =AVERAGE(K13:O13) -> 87.754527
... A34: yeast | B34: =Training!A34 -> 62.005055 | C34: =Training!B34 -> 63.689975 | D34: =Training!C34 -> 62.847515 | E34: =Training!D34 -> 62.931761 | F34: =Training!E34 -> 62.037037 | G34: =AVERAGE(B34:F34) -> 62.702268 | J34: yeast | K34: =Test!A34 -> 59.93266 | L34: =Test!B34 -> 56.902357 | M34: =Test!C34 -> 52.525253 | N34: =Test!D34 -> 55.218855 | O34: =Test!E34 -> 56.756757 | P34: =AVERAGE(K34:O34) -> 56.267176
A36: Mean | G36: =AVERAGE(G2:G34) -> 87.964595 | J36: Mean | P36: =AVERAGE(P2:P34) -> 79.200474

Sheet 2_1
A1: Dataset | B1: pt1 | C1: pt2 | D1: pt3 | E1: pt4 | F1: pt5 | G1: Mean | J1: Dataset | K1: pt1 | L1: pt2 | M1: pt3 | N1: pt4 | O1: pt5 | P1: Mean
A2: appendicitis | B2: =Training!F2 -> 95.238095 | C2: =Training!G2 -> 98.823529 | D2: =Training!H2 -> 96.470588 | E2: =Training!I2 -> 95.294118 | F2: =Training!J2 -> 96.470588 | G2: =AVERAGE(B2:F2) -> 96.459384 | J2: appendicitis | K2: =Test!F2 -> 86.363636 | L2: =Test!G2 -> 85.714286 | M2: =Test!H2 -> 85.714286 | N2: =Test!I2 -> 90.47619 | O2: =Test!J2 -> 85.714286 | P2: =AVERAGE(K2:O2) -> 86.796537
A3: balance | B3: =Training!F3 -> 87 | C3: =Training!G3 -> 87 | D3: =Training!H3 -> 84.6 | E3: =Training!I3 -> 86.2 | F3: =Training!J3 -> 87 | G3: =AVERAGE(B3:F3) -> 86.36 | J3: balance | K3: =Test!F3 -> 84.8 | L3: =Test!G3 -> 79.2 | M3: =Test!H3 -> 84.8 | N3: =Test!I3 -> 82.4 | O3: =Test!J3 -> 82.4 | P3: =AVERAGE(K3:O3) -> 82.72
A4: banana | B4: =Training!F4 -> 87.688679 | C4: =Training!G4 -> 88.066038 | D4: =Training!H4 -> 86.34434 | E4: =Training!I4 -> 86.792453 | F4: =Training!J4 -> 87.146226 | G4: =AVERAGE(B4:F4) -> 87.207547 | J4: banana | K4: =Test!F4 -> 86.320755 | L4: =Test!G4 -> 84.433962 | M4: =Test!H4 -> 86.037736 | N4: =Test!I4 -> 84.245283 | O4: =Test!J4 -> 86.981132 | P4: =AVERAGE(K4:O4) -> 85.603774
A5: bands | B5: =Training!F5 -> 89.655172 | C5: =Training!G5 -> 87.372014 | D5: =Training!H5 -> 85.56701 | E5: =Training!I5 -> 88.435374 | F5: =Training!J5 -> 85.616438 | G5: =AVERAGE(B5:F5) -> 87.329202 | J5: bands | K5: =Test!F5 -> 69.333333 | L5: =Test!G5 -> 73.611111 | M5: =Test!H5 -> 66.216216 | N5: =Test!I5 -> 70.422535 | O5: =Test!J5 -> 75.342466 | P5: =AVERAGE(K5:O5) -> 70.985132
A6: bupa | B6: =Training!F6 -> 77.898551 | C6: =Training!G6 -> 80.072464 | D6: =Training!H6 -> 77.898551 | E6: =Training!I6 -> 78.26087 | F6: =Training!J6 -> 80.434783 | G6: =AVERAGE(B6:F6) -> 78.913043 | J6: bupa | K6: =Test!F6 -> 63.768116 | L6: =Test!G6 -> 65.217391 | M6: =Test!H6 -> 65.217391 | N6: =Test!I6 -> 52.173913 | O6: =Test!J6 -> 68.115942 | P6: =AVERAGE(K6:O6) -> 62.898551
A7: cleveland | B7: =Training!F7 -> 87.341772 | C7: =Training!G7 -> 90.7173 | D7: =Training!H7 -> 89.07563 | E7: =Training!I7 -> 90.336134 | F7: =Training!J7 -> 89.495798 | G7: =AVERAGE(B7:F7) -> 89.393327 | J7: cleveland | K7: =Test!F7 -> 60 | L7: =Test!G7 -> 58.333333 | M7: =Test!H7 -> 61.016949 | N7: =Test!I7 -> 52.542373 | O7: =Test!J7 -> 49.152542 | P7: =AVERAGE(K7:O7) -> 56.20904
A8: contraceptive | B8: =Training!F8 -> 59.847199 | C8: =Training!G8 -> 60.356537 | D8: =Training!H8 -> 60.441426 | E8: =Training!I8 -> 59.796438 | F8: =Training!J8 -> 60.899067 | G8: =AVERAGE(B8:F8) -> 60.268133 | J8: contraceptive | K8: =Test!F8 -> 50.169492 | L8: =Test!G8 -> 49.491525 | M8: =Test!H8 -> 52.20339 | N8: =Test!I8 -> 47.278912 | O8: =Test!J8 -> 46.938776 | P8: =AVERAGE(K8:O8) -> 49.216419
A9: ecoli | B9: =Training!F9 -> 90.671642 | C9: =Training!G9 -> 90.70632 | D9: =Training!H9 -> 90.70632 | E9: =Training!I9 -> 90.334572 | F9: =Training!J9 -> 89.591078 | G9: =AVERAGE(B9:F9) -> 90.401986 | J9: ecoli | K9: =Test!F9 -> 69.117647 | L9: =Test!G9 -> 82.089552 | M9: =Test!H9 -> 74.626866 | N9: =Test!I9 -> 76.119403 | O9: =Test!J9 -> 82.089552 | P9: =AVERAGE(K9:O9) -> 76.808604
A10: glass | B10: =Training!F10 -> 84.210526 | C10: =Training!G10 -> 87.134503 | D10: =Training!H10 -> 87.719298 | E10: =Training!I10 -> 80.116959 | F10: =Training!J10 -> 83.139535 | G10: =AVERAGE(B10:F10) -> 84.464164 | J10: glass | K10: =Test!F10 -> 60.465116 | L10: =Test!G10 -> 55.813953 | M10: =Test!H10 -> 62.790698 | N10: =Test!I10 -> 67.44186 | O10: =Test!J10 -> 69.047619 | P10: =AVERAGE(K10:O10) -> 63.111849
A11: haberman | B11: =Training!F11 -> 83.196721 | C11: =Training!G11 -> 84.081633 | D11: =Training!H11 -> 84.897959 | E11: =Training!I11 -> 84.081633 | F11: =Training!J11 -> 82.857143 | G11: =AVERAGE(B11:F11) -> 83.823018 | J11: haberman | K11: =Test!F11 -> 75.806452 | L11: =Test!G11 -> 68.852459 | M11: =Test!H11 -> 73.770492 | N11: =Test!I11 -> 68.852459 | O11: =Test!J11 -> 73.770492 | P11: =AVERAGE(K11:O11) -> 72.210471
A12: hayes-roth | B12: =Training!F12 -> 89.52381 | C12: =Training!G12 -> 91.428571 | D12: =Training!H12 -> 91.509434 | E12: =Training!I12 -> 91.509434 | F12: =Training!J12 -> 91.509434 | G12: =AVERAGE(B12:F12) -> 91.096137 | J12: hayes-roth | K12: =Test!F12 -> 88.888889 | L12: =Test!G12 -> 77.777778 | M12: =Test!H12 -> 84.615385 | N12: =Test!I12 -> 73.076923 | O12: =Test!J12 -> 73.076923 | P12: =AVERAGE(K12:O12) -> 79.487179
A13: ion | B13: =Training!F13 -> 99.285714 | C13: =Training!G13 -> 98.932384 | D13: =Training!H13 -> 99.288256 | E13: =Training!I13 -> 98.932384 | F13: =Training!J13 -> 98.576512 | G13: =AVERAGE(B13:F13) -> 99.00305 | J13: ion | K13: =Test!F13 -> 77.464789 | L13: =Test!G13 -> 88.571429 | M13: =Test!H13 -> 87.142857 | N13: =Test!I13 -> 95.714286 | O13: =Test!J13 -> 87.142857 | P13: =AVERAGE(K13:O13) -> 87.207243
... A34: yeast | B34: =Training!F34 -> 61.162595 | C34: =Training!G34 -> 63.100253 | D34: =Training!H34 -> 64.026959 | E34: =Training!I34 -> 64.026959 | F34: =Training!J34 -> 62.457912 | G34: =AVERAGE(B34:F34) -> 62.954935 | J34: yeast | K34: =Test!F34 -> 57.575758 | L34: =Test!G34 -> 58.585859 | M34: =Test!H34 -> 54.208754 | N34: =Test!I34 -> 57.912458 | O34: =Test!J34 -> 57.432432 | P34: =AVERAGE(K34:O34) -> 57.143052
A36: Mean | G36: =AVERAGE(G2:G34) -> 87.827445 | J36: Mean | P36: =AVERAGE(P2:P34) -> 79.104333

Sheet 3_1
A1: Dataset | B1: pt1 | C1: pt2 | D1: pt3 | E1: pt4 | F1: pt5 | G1: Mean | J1: Dataset | K1: pt1 | L1: pt2 | M1: pt3 | N1: pt4 | O1: pt5 | P1: Mean
A2: appendicitis | B2: =Training!K2 -> 95.238095 | C2: =Training!L2 -> 95.294118 | D2: =Training!M2 -> 100 | E2: =Training!N2 -> 95.294118 | F2: =Training!O2 -> 96.470588 | G2: =AVERAGE(B2:F2) -> 96.459384 | J2: appendicitis | K2: =Test!K2 -> 86.363636 | L2: =Test!L2 -> 76.190476 | M2: =Test!M2 -> 85.714286 | N2: =Test!N2 -> 85.714286 | O2: =Test!O2 -> 76.190476 | P2: =AVERAGE(K2:O2) -> 82.034632
A3: balance | B3: =Training!K3 -> 86.4 | C3: =Training!L3 -> 86.6 | D3: =Training!M3 -> 85.8 | E3: =Training!N3 -> 86.4 | F3: =Training!O3 -> 86.2 | G3: =AVERAGE(B3:F3) -> 86.28 | J3: balance | K3: =Test!K3 -> 72 | L3: =Test!L3 -> 76 | M3: =Test!M3 -> 81.6 | N3: =Test!N3 -> 83.2 | O3: =Test!O3 -> 76 | P3: =AVERAGE(K3:O3) -> 77.76
A4: banana | B4: =Training!K4 -> 84.033019 | C4: =Training!L4 -> 85.117925 | D4: =Training!M4 -> 85.141509 | E4: =Training!N4 -> 84.103774 | F4: =Training!O4 -> 85.424528 | G4: =AVERAGE(B4:F4) -> 84.764151 | J4: banana | K4: =Test!K4 -> 84.622642 | L4: =Test!L4 -> 84.90566 | M4: =Test!M4 -> 83.396226 | N4: =Test!N4 -> 84.622642 | O4: =Test!O4 -> 86.132075 | P4: =AVERAGE(K4:O4) -> 84.735849
A5: bands | B5: =Training!K5 -> 90 | C5: =Training!L5 -> 88.054608 | D5: =Training!M5 -> 88.316151 | E5: =Training!N5 -> 85.034014 | F5: =Training!O5 -> 86.643836 | G5: =AVERAGE(B5:F5) -> 87.609722 | J5: bands | K5: =Test!K5 -> 68 | L5: =Test!L5 -> 62.5 | M5: =Test!M5 -> 72.972973 | N5: =Test!N5 -> 64.788732 | O5: =Test!O5 -> 69.863014 | P5: =AVERAGE(K5:O5) -> 67.624944
A6: bupa | B6: =Training!K6 -> 78.26087 | C6: =Training!L6 -> 79.710145 | D6: =Training!M6 -> 78.985507 | E6: =Training!N6 -> 79.710145 | F6: =Training!O6 -> 78.623188 | G6: =AVERAGE(B6:F6) -> 79.057971 | J6: bupa | K6: =Test!K6 -> 60.869565 | L6: =Test!L6 -> 63.768116 | M6: =Test!M6 -> 66.666667 | N6: =Test!N6 -> 62.318841 | O6: =Test!O6 -> 71.014493 | P6: =AVERAGE(K6:O6) -> 64.927536
A7: cleveland | B7: =Training!K7 -> 86.919831 | C7: =Training!L7 -> 90.295359 | D7: =Training!M7 -> 89.915966 | E7: =Training!N7 -> 90.336134 | F7: =Training!O7 -> 89.07563 | G7: =AVERAGE(B7:F7) -> 89.308584 | J7: cleveland | K7: =Test!K7 -> 61.666667 | L7: =Test!L7 -> 56.666667 | M7: =Test!M7 -> 55.932203 | N7: =Test!N7 -> 50.847458 | O7: =Test!O7 -> 50.847458 | P7: =AVERAGE(K7:O7) -> 55.19209
A8: contraceptive | B8: =Training!K8 -> 58.149406 | C8: =Training!L8 -> 60.101868 | D8: =Training!M8 -> 59.083192 | E8: =Training!N8 -> 59.287532 | F8: =Training!O8 -> 58.608991 | G8: =AVERAGE(B8:F8) -> 59.046198 | J8: contraceptive | K8: =Test!K8 -> 49.830508 | L8: =Test!L8 -> 48.135593 | M8: =Test!M8 -> 50.169492 | N8: =Test!N8 -> 46.598639 | O8: =Test!O8 -> 48.639456 | P8: =AVERAGE(K8:O8) -> 48.674738
A9: ecoli | B9: =Training!K9 -> 89.925373 | C9: =Training!L9 -> 91.078067 | D9: =Training!M9 -> 91.078067 | E9: =Training!N9 -> 89.219331 | F9: =Training!O9 -> 91.821561 | G9: =AVERAGE(B9:F9) -> 90.62448 | J9: ecoli | K9: =Test!K9 -> 70.588235 | L9: =Test!L9 -> 82.089552 | M9: =Test!M9 -> 74.626866 | N9: =Test!N9 -> 73.134328 | O9: =Test!O9 -> 85.074627 | P9: =AVERAGE(K9:O9) -> 77.102722
A10: glass | B10: =Training!K10 -> 84.795322 | C10: =Training!L10 -> 84.795322 | D10: =Training!M10 -> 86.549708 | E10: =Training!N10 -> 84.210526 | F10: =Training!O10 -> 83.72093 | G10: =AVERAGE(B10:F10) -> 84.814361 | J10: glass | K10: =Test!K10 -> 67.44186 | L10: =Test!L10 -> 62.790698 | M10: =Test!M10 -> 60.465116 | N10: =Test!N10 -> 60.465116 | O10: =Test!O10 -> 71.428571 | P10: =AVERAGE(K10:O10) -> 64.518272
A11: haberman | B11: =Training!K11 -> 82.786885 | C11: =Training!L11 -> 82.44898 | D11: =Training!M11 -> 84.081633 | E11: =Training!N11 -> 84.897959 | F11: =Training!O11 -> 83.673469 | G11: =AVERAGE(B11:F11) -> 83.577785 | J11: haberman | K11: =Test!K11 -> 75.806452 | L11: =Test!L11 -> 67.213115 | M11: =Test!M11 -> 68.852459 | N11: =Test!N11 -> 75.409836 | O11: =Test!O11 -> 75.409836 | P11: =AVERAGE(K11:O11) -> 72.53834
